try:
    value = int(input('Enter a natural number: '))
    print('The reciprocal of', value, 'is', 1/value)        
except ValueError:
    print('I do not know what to do.')    
except ZeroDivisionError:
    print('Division by zero is not allowed in our Universe.') 

# if one of the branches is executed, all the other branches remain idle.

try:
    value = int(input('Enter a natural number: '))
    print('The reciprocal of', value, 'is', 1/value)        
except ValueError:
    print('I do not know what to do.')    
except ZeroDivisionError:
    print('Division by zero is not allowed in our Universe.')    
except:
    print('Something strange has happened here... Sorry!')

# except branch, but this time it has no exception name specified â€“ we can say it's anonymous or 
# (what is closer to its actual role) it's the default.